<!-- ur官方urdf文件导出xml文件 + 参考mujoco-UR5-2-finger.xml文件 合成 -->

<mujoco model="ur3">

    <body mocap="true" name="robot0:mocap" pos="0 0 0">
        <geom conaffinity="0" contype="0" pos="0 0 0" rgba="0 0.5 0 0.7" size="0.005 0.005 0.005" type="box"></geom>
        <geom conaffinity="0" contype="0" pos="0 0 0" rgba="0 0.5 0 0.1" size="1 0.005 0.005" type="box"></geom>
        <geom conaffinity="0" contype="0" pos="0 0 0" rgba="0 0.5 0 0.1" size="0.005 1 0.001" type="box"></geom>
        <geom conaffinity="0" contype="0" pos="0 0 0" rgba="0 0.5 0 0.1" size="0.005 0.005 1" type="box"></geom>
    </body>


    <!--Robot UR3e-->
    <!-- base_link -->
    <body childclass="robot0:ur3e" name="robot0:base_link" pos="0 0 1.0">
        <!--            <joint armature="0.0001" axis="1 0 0" damping="1e+11" name="robot0:slide0" pos="0 0 0" type="slide"></joint>-->
        <!--            <joint armature="0.0001" axis="0 1 0" damping="1e+11" name="robot0:slide1" pos="0 0 0" type="slide"></joint>-->
        <!--            <joint armature="0.0001" axis="0 0 1" damping="1e+11" name="robot0:slide2" pos="0 0 0" type="slide"></joint>-->
        <inertial pos="0 0 0" quat="0.5 0.5 -0.5 0.5" mass="4" diaginertia="0.0072 0.00443333 0.00443333"/>
        <geom mesh="robot0:base_link" name="robot0:base_link" material="robot0:base_mat" class="robot0:base_color"/>

        <!-- shoulder_link -->
        <body name="robot0:shoulder_link" pos="0 0 0.152">
            <inertial pos="0 0 0" mass="2" diaginertia="0.00809316 0.00809316 0.005625"/>
            <joint name="robot0:shoulder_pan_joint" pos="0 0 0" axis="0 0 1" limited="true" range="-3.14159 3.14159"/>
            <geom mesh="robot0:shoulder_link" name="robot0:shoulder_link" material="robot0:arm_mat" class="robot0:link1_color"/>

            <!-- upper_arm_link -->
            <body name="robot0:upperarm_link" pos="0 0.12 0" quat="0.707107 0 0.707107 0">
                <inertial pos="0 0 0.122" mass="3.42" diaginertia="0.0217771 0.0217771 0.00961875"/>
                <joint name="robot0:shoulder_lift_joint" pos="0 0 0" axis="0 1 0" limited="true"
                       range="-3.14159 3.14159"/>
                <geom name="robot0:upperarm_link" mesh="robot0:upperarm_link" material="robot0:arm_mat" class="robot0:link2_color"/>

                <!-- forearm_link -->
                <body name="robot0:forearm_link" pos="0 -0.093 0.244">
                    <inertial pos="0 0 0.1065" mass="1.26" diaginertia="0.00653562 0.00653562 0.00354375"/>
                    <joint name="robot0:elbow_joint" pos="0 0 0" axis="0 1 0" limited="true"
                           range="-3.14159 3.14159"/>
                    <geom name="robot0:forearm_link" mesh="robot0:forearm_link" material="robot0:arm_mat" class="robot0:link3_color"/>

                    <!-- wrist_1_link -->
                    <body name="robot0:wrist_1_link" pos="0 0 0.213" quat="0.707107 0 0.707107 0">
                        <inertial pos="0 0.104 0" quat="0.5 0.5 -0.5 0.5" mass="0.8"
                                  diaginertia="0.00225 0.002085 0.002085"/>
                        <joint name="robot0:wrist_1_joint" pos="0 0 0" axis="0 1 0" limited="true"
                               range="-3.14159 3.14159"/>
                        <geom mesh="robot0:wrist_1_link" material="robot0:arm_mat" name="robot0:wrist_1_link" class="robot0:link4_color"/>

                        <!-- wrist_2_link -->
                        <body name="robot0:wrist_2_link" pos="0 0.104 0">
                            <inertial pos="0 0 0.085" quat="0.5 0.5 -0.5 0.5" mass="0.8"
                                      diaginertia="0.00225 0.002085 0.002085"/>
                            <joint name="robot0:wrist_2_joint" pos="0 0 0" axis="0 0 1" limited="true"
                                   range="-3.14159 3.14159"/>
                            <geom mesh="robot0:wrist_2_link" material="robot0:arm_mat" name="robot0:wrist_2_link"
                                  class="robot0:link5_color"/>

                            <!-- wrist_3_link -->
                            <body name="robot0:wrist_3_link" pos="0 0 0.085">
                                <inertial pos="0 0.0710313 0" quat="0.707107 0 0 0.707107" mass="0.351"
                                          diaginertia="0.000179217 0.000141187 0.000141187"/>
                                <joint name="robot0:wrist_3_joint" pos="0 0 0" axis="0 1 0"
                                       limited="true"
                                       range="-3.14159 3.14159"/>
                                <geom mesh="robot0:wrist_3_link" material="robot0:arm_mat" name="robot0:wrist_3_link"
                                      class="robot0:link6_color"/>

                                <!-- ee_link -->
                                <body name="robot0:ee_link" pos="0 0.0823 0" quat="0.707107 0 0 0.707107">
                                    <inertial pos="-0.01 0 0" mass="0.001"
                                              diaginertia="1.66667e-08 1.66667e-08 1.66667e-08"/>
                                    <geom size="0.005 0.005 0.005" pos="-0.01 0 0" type="box"/>


                                    <!--GRIPPER     robot0:gripper_link:用来mocap控制机械臂移动的关节-->
                                    <body euler="0 0 0" name="robot0:gripper_link" pos="0.09 0 0">
                                        <!--用来获取手爪中心点的site-->
                                        <site name="robot0:grip" pos="0.05 0 0" rgba="1 0 0 1"
                                              size="0.002 0.002 1.02" type="box" quat="0.707107 0 0 0.707107"></site>

                                        <body name="robot0:robotiq_85_base_link" pos="-0.08 0 0" quat="0.5 0.5 0.5 0.5 ">
                                            <inertial pos="0.00021987 -2.3546e-10 0.030163"
                                                      quat="0.707058 0.00723369 0.00723345 0.707081" mass="0.30915"
                                                      diaginertia="0.00030737 0.000289758 0.000199102"/>
                                            <geom type="mesh" rgba="0.1 0.1 0.1 1"
                                                  mesh="robot0:robotiq_85_base_link_coarse"/>

                                            <body name="robot0:left_inner_knuckle" pos="0.0127 0 0.0693075">
                                                <inertial pos="0.0170975 -3.93809e-10 0.0224918"
                                                          quat="0.947655 0 -0.319297 0" mass="0.0110931"
                                                          diaginertia="5.59353e-06 3.96549e-06 1.88108e-06"/>
                                                <geom type="mesh" rgba="0.1 0.1 0.1 1"
                                                      mesh="robot0:inner_knuckle_coarse"/>
                                                <joint name="robot0:base_to_lik" pos="0 0 0"
                                                       axis="0 1 0"
                                                       limited="true" range="-1 1"/>

                                                <body name="robot0:left_inner_finger" pos="0.0345853 0 0.045497">
                                                    <inertial pos="0.00602756 0 0.00669926"
                                                              quat="0.699065 0.106339 0.106339 0.699065"
                                                              mass="0.00724255"
                                                              diaginertia="1.70064e-06 1.58577e-06 3.69621e-07"/>
                                                    <geom type="mesh" rgba="0.1 0.1 0.1 1"
                                                          mesh="robot0:inner_finger_coarse" friction="1 1 1"/>

                                                    <!--以render显示方向来看: x 朝右 y 朝前方 z 朝下-->
                                                    <body childclass="robot0:ur3eGripper" name="robot0:l_grip_sup"
                                                          pos="-0.0075 0 0.043" quat="0.707 0.707 0 0">
                                                        <inertial diaginertia="0.1 0.1 0.1" mass="0.1" pos="-0.01 0 0"></inertial>
                                                        <geom pos="0 0 0" size="0.002 0.01 0.02" type="cylinder"
                                                              name="robot0:l_grip_sup" material="robot0:gripper_finger_mat" condim="4"
                                                              friction="1 1 1"></geom>
                                                    </body>

                                                </body>
                                            </body>

                                            <body name="robot0:right_inner_knuckle"
                                                  pos="-0.0127 0 0.0693075"
                                                  quat="0 0 0 1">
                                                <inertial pos="0.0168606 3.93808e-10 0.02267"
                                                          quat="0.949317 0 -0.314322 0" mass="0.0110931"
                                                          diaginertia="5.59353e-06 3.96549e-06 1.88108e-06"/>
                                                <geom type="mesh" rgba="0.1 0.1 0.1 1"
                                                      mesh="robot0:inner_knuckle_coarse"/>
                                                <joint name="robot0:base_to_rik" pos="0 0 0"
                                                       axis="0 1 0"
                                                       limited="true" range="-1 1"/>

                                                <body name="robot0:right_inner_finger" pos="0.034106 0 0.0458574">
                                                    <inertial pos="0.00602756 0 0.00669926"
                                                              quat="0.699065 0.106339 0.106339 0.699065"
                                                              mass="0.00724255"
                                                              diaginertia="1.70064e-06 1.58577e-06 3.69621e-07"/>
                                                    <geom type="mesh" rgba="0.1 0.1 0.1 1"
                                                          mesh="robot0:inner_finger_coarse" friction="1 1 1"/>

                                                    <body childclass="robot0:ur3eGripper" name="robot0:r_grip_sup"
                                                          pos="-0.0075 0 0.043" quat="0.707 0.707 0 0">
                                                        <inertial diaginertia="0.1 0.1 0.1" mass="0.1" pos="-0.01 0 0"></inertial>
                                                        <geom pos="0 0 0" size="0.002 0.01 0.02" type="cylinder"
                                                              name="robot0:r_grip_sup" material="robot0:gripper_finger_mat" condim="4"
                                                              friction="1 1 1"></geom>
                                                    </body>
                                                </body>
                                            </body>

                                        </body>
                                    </body>


                                </body>
                            </body>
                        </body>
                    </body>
                </body>
            </body>
        </body>
    </body>
</mujoco>
