<!-- ur官方urdf文件导出xml文件 + 参考mujoco-UR5-2-finger.xml文件 合成 -->

<mujoco model="ur3">
    <!--    <compiler-->
    <!--            angle="radian"-->
    <!--            meshdir="meshs_ur3e/"-->
    <!--            inertiafromgeom="true"-->
    <!--            texturedir="textures/"-->
    <!--    />-->
    <compiler
            angle="radian"
            coordinate="local"
            meshdir="meshs_ur3e/"
            texturedir="textures/"
    ></compiler>
    <option timestep="0.002">
        <flag warmstart="enable"></flag>
    </option>
    <!--    <option-->
    <!--            timestep="1e-3"-->
    <!--            iterations="100"-->
    <!--            tolerance="1e-10"-->
    <!--            impratio="10"-->
    <!--    >-->
    <!--        <flag warmstart="enable"></flag>-->
    <!--    </option>-->

    <default>
        <!--        <site rgba="1 0 0 1" type="ellipsoid" group="3"/>-->
        <geom contype='1' conaffinity='1' condim='4' margin="1e-3" solref=".01 1" solimp=".99 .99 .01"/>
        <joint armature="0.01" damping=".1"/>
        <default class="UR3">
            <joint damping='65'/>
        </default>
        <default class="UR3e">
            <joint damping='45'/>
        </default>
        <default class="GRIPPER">
            <joint damping='5'/>
        </default>

    </default>

    <visual>
        <headlight ambient="0.8 0.8 0.8" diffuse="0.4 0.4 0.4" specular="0.5 0.5 0.5" active="1"/>
        <map fogstart="3" fogend="5" znear="0.05"/>
        <quality shadowsize="2048"/>
        <scale framelength="0.1"
               framewidth="0.005"
               contactwidth="0.1"
               contactheight="0.005"
               forcewidth="0.01"
        />
    </visual>

    <size njmax="500" nconmax="100"/>

    <asset>
        <!--Meshes-->
        <mesh name="base" file="base.stl"/>
        <mesh name="shoulder" file="shoulder.stl"/>
        <mesh name="upperarm" file="upperarm.stl"/>
        <mesh name="forearm" file="forearm.stl"/>
        <mesh name="wrist1" file="wrist1.stl"/>
        <mesh name="wrist2" file="wrist2.stl"/>
        <mesh name="wrist3" file="wrist3.stl"/>
        <mesh name="robotiq_85_base_link_coarse" file="robotiq_85_base_link_coarse.STL"/>
        <mesh name="inner_knuckle_coarse" file="inner_knuckle_coarse.STL"/>
        <mesh name="inner_finger_coarse" file="inner_finger_coarse.STL"/>
        <mesh name="outer_knuckle_coarse" file="outer_knuckle_coarse.STL"/>
        <mesh name="outer_finger_coarse" file="outer_finger_coarse.STL"/>


        <!--Textures-->
        <texture name="ur5_tex" type="2d" builtin="flat" height="32" width="32" rgb1="0.45 0.45 0.45"/>
        <texture name="gripper_tex" type="2d" builtin="flat" height="32" width="32" rgb1="0.45 0.45 0.45" rgb2="0 0 0"/>
        <texture name="bench_tex" type="2d" builtin="flat" height="32" width="32" rgb1="0.7 0.7 0.7"/>
        <texture name="sky_tex" type="skybox" builtin="gradient" width="100" height="100" rgb1="1 1 1"
                 rgb2="0.3 0.3 0.8"/>
        <texture name="texgeom" type="cube" builtin="flat" mark="cross" width="127" height="1278" rgb1="0.8 0.6 0.4"
                 rgb2="0.8 0.6 0.4" markrgb="1 1 1" random="0.01"/>
        <texture name="floor_tex" type="2d" builtin="checker" rgb1=".2 .3 .4" rgb2=".1 .2 .3" width="100" height="100"/>
        <texture name="wood" type="cube" file="wood2.png"/>
        <texture name="metal" type="cube" file="metal2.png"/>
        <!--Materials-->
        <material name="ur5_mat" texture="ur5_tex" shininess="0.1" specular="0.9" reflectance="0.3"/>
        <material name="gripper_mat" texture="gripper_tex" shininess="0.1" specular="0.75" reflectance="0.4"/>
        <material name='floor_mat' texture="floor_tex" shininess="0.8" texrepeat="10 10" specular="0.7"
                  reflectance="0.1"/>
        <material name='geom' texture="texgeom" texuniform="true"/>
        <material name="bench_mat" texture="metal" shininess="0.1" specular="0.5" reflectance="0.2"/>
        <material name="tablecube" texture="wood" rgba=".8 .8 .8 1"/>

    </asset>

    <!--Contacts-->
    <contact>
        <exclude body1="base_link" body2="shoulder_link"/>
        <exclude body1="shoulder_link" body2="upper_arm_link"/>
        <exclude body1="upper_arm_link" body2="forearm_link"/>
        <exclude body1="forearm_link" body2="wrist_1_link"/>
        <exclude body1="wrist_1_link" body2="wrist_2_link"/>
        <exclude body1="wrist_2_link" body2="wrist_3_link"/>
        <exclude body1="ee_link" body2="wrist_3_link"/>
    </contact>


    <worldbody>
        <!--Lighting parameters-->
        <light name="light3" mode="targetbody" target="box_link" directional="true" pos="1 -1 3"/>
        <!--Camera parameters-->
        <!--        <camera name="main1" mode="fixed" target="ee_link" pos="2 2 2.7" axisangle="2 2 -2 1"/>-->
        <!--        <camera name="top_down" mode="fixed" target="ee_link" pos="0 -0.6 2.0" axisangle="2 2 2 0"/>-->
        <!--        <camera name="side" mode="fixed" target="ee_link" pos="0.8 -0.6 1.0" quat="0.5 0.5 0.5 0.5"/>-->
        <!--Floor Property-->
        <geom name='floor' material="floor_mat" pos='0 0 0' size='2.5 2.5 0.1' type='plane'/>
        <body name="floor" pos="0. 0. 0.">
            <site name="target0" pos="0.0 0.0 1.0" size="0.02 0.02 0.02" rgba="1 0 0 1" type="sphere"></site>>
            <!--            <geom material="floor_mat" pos='0 0 1' size='0.2 0.2 0.2' type='sphere'/>-->
        </body>


        <!-- colosrs 
        106, 12, 11    0.4156862745 0.0470588235 0.0431372549 red
        251, 202, 3    0.9843137255 0.7921568627 0.0117647059
        185, 125, 16   0.72549019 0.49019607 0.062745098            -->
        <!--        <geom name="floor0" pos="0. 0. 0." size="0.85 0.7 1" type="plane" condim="3" material="floor_mat"></geom>-->


        <body mocap="true" name="robot0:mocap" pos="0 0 0">
            <geom conaffinity="0" contype="0" pos="0 0 0" rgba="0 0.5 0 0.7" size="0.005 0.005 0.005" type="box"></geom>
            <geom conaffinity="0" contype="0" pos="0 0 0" rgba="0 0.5 0 0.1" size="1 0.005 0.005" type="box"></geom>
            <geom conaffinity="0" contype="0" pos="0 0 0" rgba="0 0.5 0 0.1" size="0.005 1 0.001" type="box"></geom>
            <geom conaffinity="0" contype="0" pos="0 0 0" rgba="0 0.5 0 0.1" size="0.005 0.005 1" type="box"></geom>
        </body>


        <!--Robot UR3e-->
        <body name="box_link" pos="0 0 0.5">
            <geom size="0.5 0.6 .5" pos="0.4 0 0 " type="box" material="bench_mat"/>
            <inertial pos="0 0 0" mass="1000" diaginertia="0 0 0"/>
        </body>

        <!-- base_link -->
        <!--            <body name="base_link" pos="0 0 0.535" quat="0.707107 0 0 -0.707107">-->
        <body name="base_link" pos="0 0 1.0">
            <!--            <joint armature="0.0001" axis="1 0 0" damping="1e+11" name="robot0:slide0" pos="0 0 0" type="slide"></joint>-->
            <!--            <joint armature="0.0001" axis="0 1 0" damping="1e+11" name="robot0:slide1" pos="0 0 0" type="slide"></joint>-->
            <!--            <joint armature="0.0001" axis="0 0 1" damping="1e+11" name="robot0:slide2" pos="0 0 0" type="slide"></joint>-->
            <inertial pos="0 0 0" quat="0.5 0.5 -0.5 0.5" mass="4" diaginertia="0.0072 0.00443333 0.00443333"/>
            <geom type="mesh" mesh="base" material="ur5_mat" rgba="0.4156862745 0.0470588235 0.0431372549 1"/>

            <!-- shoulder_link -->
            <body name="shoulder_link" pos="0 0 0.152">
                <inertial pos="0 0 0" mass="2" diaginertia="0.00809316 0.00809316 0.005625"/>
                <joint name="robot0:shoulder_pan_joint" class="UR3e" pos="0 0 0" axis="0 0 1" limited="true"
                       range="-3.14159 3.14159"/>
                <geom type="mesh" mesh="shoulder" material="ur5_mat" rgba=" 0.72549019 0.49019607 0.062745098 1"/>

                <!-- upper_arm_link -->
                <body name="upper_arm_link" pos="0 0.12 0" quat="0.707107 0 0.707107 0">
                    <inertial pos="0 0 0.122" mass="3.42" diaginertia="0.0217771 0.0217771 0.00961875"/>
                    <joint name="robot0:shoulder_lift_joint" class="UR3e" pos="0 0 0" axis="0 1 0" limited="true"
                           range="-3.14159 3.14159"/>
                    <geom type="mesh" mesh="upperarm" material="ur5_mat"
                          rgba="0.4156862745 0.0470588235 0.0431372549 1"/>

                    <!-- forearm_link -->
                    <body name="forearm_link" pos="0 -0.093 0.244">

                        <inertial pos="0 0 0.1065" mass="1.26" diaginertia="0.00653562 0.00653562 0.00354375"/>
                        <joint name="robot0:elbow_joint" class="UR3e" pos="0 0 0" axis="0 1 0" limited="true"
                               range="-3.14159 3.14159"/>
                        <geom type="mesh" mesh="forearm" material="ur5_mat"
                              rgba="0.4156862745 0.0470588235 0.0431372549 1"/>

                        <!-- wrist_1_link -->
                        <body name="wrist_1_link" pos="0 0 0.213" quat="0.707107 0 0.707107 0">
                            <inertial pos="0 0.104 0" quat="0.5 0.5 -0.5 0.5" mass="0.8"
                                      diaginertia="0.00225 0.002085 0.002085"/>
                            <joint name="robot0:wrist_1_joint" class="UR3e" pos="0 0 0" axis="0 1 0" limited="true"
                                   range="-3.14159 3.14159"/>
                            <geom type="mesh" mesh="wrist1" material="ur5_mat"
                                  rgba="0.72549019 0.49019607 0.062745098 1"/>

                            <!-- wrist_2_link -->
                            <body name="wrist_2_link" pos="0 0.104 0">
                                <inertial pos="0 0 0.085" quat="0.5 0.5 -0.5 0.5" mass="0.8"
                                          diaginertia="0.00225 0.002085 0.002085"/>
                                <joint name="robot0:wrist_2_joint" class="UR3e" pos="0 0 0" axis="0 0 1" limited="true"
                                       range="-3.14159 3.14159"/>
                                <geom type="mesh" mesh="wrist2" material="ur5_mat"
                                      rgba="0.4156862745 0.0470588235 0.0431372549 1"/>

                                <!-- wrist_3_link -->
                                <body name="wrist_3_link" pos="0 0 0.085">
                                    <inertial pos="0 0.0710313 0" quat="0.707107 0 0 0.707107" mass="0.351"
                                              diaginertia="0.000179217 0.000141187 0.000141187"/>
                                    <joint name="robot0:wrist_3_joint" class="UR3e" pos="0 0 0" axis="0 1 0"
                                           limited="true"
                                           range="-3.14159 3.14159"/>
                                    <geom type="mesh" mesh="wrist3" material="ur5_mat"
                                          rgba="0.72549019 0.49019607 0.062745098 1"/>

                                    <!--                                    <body name="robot0:grip" pos="0 0.24 0">-->
                                    <!--                                        <geom type="box" rgba="1 0 1 1" size="0.05 0.05 0.005"></geom>-->
                                    <!--                                    </body>-->
                                    <site name="robot0:grip" pos="0.0 0.24 0.0" rgba="1 0 1 1"
                                          size="0.01 0.01 0.01"></site>
                                    <!--末端中心的mocap标记-->
                                    <body name="mocap_link" pos="0.0 0.24 0.0" quat="0.707107 0 0 0.707107"></body>


                                    <!-- ee_link -->
                                    <body name="ee_link" pos="0 0.0823 0" quat="0.707107 0 0 0.707107">
                                        <inertial pos="-0.01 0 0" mass="0.001"
                                                  diaginertia="1.66667e-08 1.66667e-08 1.66667e-08"/>
                                        <geom size="0.005 0.005 0.005" pos="-0.01 0 0" type="box"/>


                                        <!--GRIPPER-->
                                        <!-- <joint name="ee_to_base" pos="0 0 0" axis="1 0 0" limited="true" range="0 0" /> -->
                                        <body name="robotiq_85_base_link" pos="0 0 0" quat="0.5 0.5 0.5 0.5 ">
                                            <inertial pos="0.00021987 -2.3546e-10 0.030163"
                                                      quat="0.707058 0.00723369 0.00723345 0.707081" mass="0.30915"
                                                      diaginertia="0.00030737 0.000289758 0.000199102"/>
                                            <geom type="mesh" rgba="0.1 0.1 0.1 1" friction="0.8 0.8 0.8"
                                                  mesh="robotiq_85_base_link_coarse"/>

                                            <body name="left_inner_knuckle" pos="0.0127 0 0.0693075">
                                                <inertial pos="0.0170975 -3.93809e-10 0.0224918"
                                                          quat="0.947655 0 -0.319297 0" mass="0.0110931"
                                                          diaginertia="5.59353e-06 3.96549e-06 1.88108e-06"/>
                                                <geom type="mesh" rgba="0.1 0.1 0.1 1" friction="0.8 0.8 0.8"
                                                      mesh="inner_knuckle_coarse"/>
                                                <joint name="robot0:base_to_lik" class="GRIPPER" pos="0 0 0"
                                                       axis="0 1 0"
                                                       limited="true" range="-1 1"/>

                                                <body name="left_inner_finger" pos="0.0345853 0 0.045497">
                                                    <inertial pos="0.00602756 0 0.00669926"
                                                              quat="0.699065 0.106339 0.106339 0.699065"
                                                              mass="0.00724255"
                                                              diaginertia="1.70064e-06 1.58577e-06 3.69621e-07"/>
                                                    <geom type="mesh" rgba="0.1 0.1 0.1 1" friction="0.8 0.8 0.8"
                                                          mesh="inner_finger_coarse"/>
                                                </body>
                                            </body>

                                            <body name="right_inner_knuckle" pos="-0.0127 0 0.0693075"
                                                  quat="0 0 0 1">
                                                <inertial pos="0.0168606 3.93808e-10 0.02267"
                                                          quat="0.949317 0 -0.314322 0" mass="0.0110931"
                                                          diaginertia="5.59353e-06 3.96549e-06 1.88108e-06"/>
                                                <geom type="mesh" rgba="0.1 0.1 0.1 1" friction="0.8 0.8 0.8"
                                                      mesh="inner_knuckle_coarse"/>
                                                <joint name="robot0:base_to_rik" class="GRIPPER" pos="0 0 0"
                                                       axis="0 1 0"
                                                       limited="true" range="-1 1"/>

                                                <body name="right_inner_finger" pos="0.034106 0 0.0458574">
                                                    <inertial pos="0.00602756 0 0.00669926"
                                                              quat="0.699065 0.106339 0.106339 0.699065"
                                                              mass="0.00724255"
                                                              diaginertia="1.70064e-06 1.58577e-06 3.69621e-07"/>
                                                    <geom type="mesh" rgba="0.1 0.1 0.1 1" friction="0.8 0.8 0.8"
                                                          mesh="inner_finger_coarse"/>
                                                </body>
                                            </body>
                                        </body>
                                    </body>
                                </body>
                            </body>
                        </body>
                    </body>
                </body>
            </body>

        </body>


        <!--
                <body name="box_1" pos=".0 -.6 0.95">
                    <joint armature="0" axis="1 0 0" damping="0" limited="true" name="box_1_x" pos="0 0 0" range="-5. 5." stiffness="0" type="slide" />
                    <joint armature="0" axis="0 1 0" damping="0" limited="true" name="box_1_y" pos="0 0 0" range="-5. 5." stiffness="0" type="slide" />
                    <joint armature="0" axis="0 0 1" damping="0" limited="true" name="box_1_z" pos="0 0 0" range="-2. 2." stiffness="0" type="slide" />
                    <joint armature="0" damping="0" name="box_1_rot" pos="0 0 0" stiffness="0" type="ball" />
                    <geom name="box_1" pos="0 0 0" material="tablecube" size="0.02 0.02 0.02" type="box" />
                </body> -->

        <body name="object0" pos="0.6 0. 1.025">
            <joint name="object0:joint" type="free" damping="0.01"></joint>
            <geom size="0.025 0.025 0.025" type="box" condim="3" name="object0" rgba="0.3 0.3 0.3 1" mass="1"></geom>
            <site name="object0" pos="0 0 0" size="0.02 0.02 0.02" rgba="0.3 0.3 0.3 0" type="box"></site>
        </body>


    </worldbody>

    <equality>
        <weld body1="robot0:mocap" body2="mocap_link" solimp="0.9 0.95 0.001" solref="0.02 1"></weld>
    </equality>

    <actuator>
        <position name='robot0:gripper_l' ctrllimited="true" ctrlrange="-0.3 0.3" joint='robot0:base_to_lik'
                  kp="1000" user="1"/>
        <position name='robot0:gripper_r' ctrllimited="true" ctrlrange="-0.3 0.3" joint='robot0:base_to_rik'
                  kp="1000" user="1"/>
    </actuator>
</mujoco>
