<!-- ur官方urdf文件导出xml文件 + 参考mujoco-UR5-2-finger.xml文件 合成 -->

<mujoco model="ur3">

    <body mocap="true" name="robot0:mocap" pos="0 0 0">
        <geom conaffinity="0" contype="0" pos="0 0 0" rgba="0 0.5 0 0.7" size="0.005 0.005 0.005" type="box"></geom>
        <geom conaffinity="0" contype="0" pos="0 0 0" rgba="0 0.5 0 0.1" size="1 0.005 0.005" type="box"></geom>
        <geom conaffinity="0" contype="0" pos="0 0 0" rgba="0 0.5 0 0.1" size="0.005 1 0.001" type="box"></geom>
        <geom conaffinity="0" contype="0" pos="0 0 0" rgba="0 0.5 0 0.1" size="0.005 0.005 1" type="box"></geom>
    </body>


    <!--Robot UR3e-->
    <!-- base_link -->
    <body childclass="robot0:ur3e" name="robot0:base_link" pos="0 0 1.0">
        <!--            <joint armature="0.0001" axis="1 0 0" damping="1e+11" name="robot0:slide0" pos="0 0 0" type="slide"></joint>-->
        <!--            <joint armature="0.0001" axis="0 1 0" damping="1e+11" name="robot0:slide1" pos="0 0 0" type="slide"></joint>-->
        <!--            <joint armature="0.0001" axis="0 0 1" damping="1e+11" name="robot0:slide2" pos="0 0 0" type="slide"></joint>-->
        <inertial pos="0 0 0" quat="0.5 0.5 -0.5 0.5" mass="4" diaginertia="0.0072 0.00443333 0.00443333"/>
        <geom mesh="robot0:base_link" name="robot0:base_link" material="robot0:base_mat" class="robot0:base_color"/>

        <!-- shoulder_link -->
        <body name="robot0:shoulder_link" pos="0 0 0.152">
            <inertial pos="0 0 0" mass="2" diaginertia="0.00809316 0.00809316 0.005625"/>
            <joint name="robot0:shoulder_pan_joint" pos="0 0 0" axis="0 0 1" limited="true" range="-3.14159 3.14159"/>
            <geom mesh="robot0:shoulder_link" name="robot0:shoulder_link" material="robot0:arm_mat" class="robot0:link1_color"/>

            <!-- upper_arm_link -->
            <body name="robot0:upperarm_link" pos="0 0.12 0" quat="0.707107 0 0.707107 0">
                <inertial pos="0 0 0.122" mass="3.42" diaginertia="0.0217771 0.0217771 0.00961875"/>
                <joint name="robot0:shoulder_lift_joint" pos="0 0 0" axis="0 1 0" limited="true"
                       range="-3.14159 3.14159"/>
                <geom name="robot0:upperarm_link" mesh="robot0:upperarm_link" material="robot0:arm_mat" class="robot0:link2_color"/>

                <!-- forearm_link -->
                <body name="robot0:forearm_link" pos="0 -0.093 0.244">
                    <inertial pos="0 0 0.1065" mass="1.26" diaginertia="0.00653562 0.00653562 0.00354375"/>
                    <joint name="robot0:elbow_joint" pos="0 0 0" axis="0 1 0" limited="true"
                           range="-3.14159 3.14159"/>
                    <geom name="robot0:forearm_link" mesh="robot0:forearm_link" material="robot0:arm_mat" class="robot0:link3_color"/>

                    <!-- wrist_1_link -->
                    <body name="robot0:wrist_1_link" pos="0 0 0.213" quat="0.707107 0 0.707107 0">
                        <inertial pos="0 0.104 0" quat="0.5 0.5 -0.5 0.5" mass="0.8"
                                  diaginertia="0.00225 0.002085 0.002085"/>
                        <joint name="robot0:wrist_1_joint" pos="0 0 0" axis="0 1 0" limited="true"
                               range="-3.14159 3.14159"/>
                        <geom mesh="robot0:wrist_1_link" material="robot0:arm_mat" name="robot0:wrist_1_link" class="robot0:link4_color"/>

                        <!-- wrist_2_link -->
                        <body name="robot0:wrist_2_link" pos="0 0.104 0">
                            <inertial pos="0 0 0.085" quat="0.5 0.5 -0.5 0.5" mass="0.8"
                                      diaginertia="0.00225 0.002085 0.002085"/>
                            <joint name="robot0:wrist_2_joint" pos="0 0 0" axis="0 0 1" limited="true"
                                   range="-3.14159 3.14159"/>
                            <geom  mesh="robot0:wrist_2_link" material="robot0:arm_mat" name="robot0:wrist_2_link" class="robot0:link5_color"/>

                            <!-- wrist_3_link -->
                            <body name="robot0:wrist_3_link" pos="0 0 0.085">
                                <inertial pos="0 0.0710313 0" quat="0.707107 0 0 0.707107" mass="0.351"
                                          diaginertia="0.000179217 0.000141187 0.000141187"/>
                                <joint name="robot0:wrist_3_joint" pos="0 0 0" axis="0 1 0"
                                       limited="true"
                                       range="-3.14159 3.14159"/>
                                <geom mesh="robot0:wrist_3_link" material="robot0:arm_mat" name="robot0:wrist_3_link" class="robot0:link6_color"/>

                                <!-- ee_link -->
                                <body name="robot0:ee_link" pos="0 0.0823 0" quat="0.707107 0 0 0.707107">
                                    <inertial pos="-0.01 0 0" mass="0.001"
                                              diaginertia="1.66667e-08 1.66667e-08 1.66667e-08"/>
                                    <geom size="0.005 0.005 0.005" pos="-0.01 0 0" type="box"/>


                                    <!--GRIPPER-->
                                    <body euler="0 0 0" name="robot0:gripper_link" pos="0.1565 0 0">
                                        <inertial diaginertia="0.0024 0.0019 0.0013" mass="1.5175"
                                                  pos="-0.09 -0.0001 -0.0017" quat="0 0.7071 0 0.7071"></inertial>
                                        <geom mesh="robot0:gripper_link" name="robot0:gripper_link" material="robot0:gripper_mat"></geom>

                                        <body name="robot0:gripper_camera_link" pos="0.055 0 0.0225">
                                            <body name="robot0:gripper_camera_rgb_frame" pos="0 0.02 0">
                                                <body name="robot0:gripper_camera_rgb_optical_frame" pos="0 0 0"
                                                      quat="0.5 -0.5 0.5 -0.5">
                                                    <camera euler="3.1415 0 0" fovy="50" name="gripper_camera_rgb"
                                                            pos="0 0 0"></camera>
                                                </body>
                                            </body>
                                            <body name="robot0:gripper_camera_depth_frame" pos="0 0.045 0">
                                                <body name="robot0:gripper_camera_depth_optical_frame" pos="0 0 0"
                                                      quat="0.5 -0.5 0.5 -0.5"></body>
                                            </body>
                                        </body>

                                        <body childclass="robot0:ur3eGripper" name="robot0:r_gripper_finger_link" pos="0 0.0159 0">
                                            <inertial diaginertia="0.1 0.1 0.1" mass="4" pos="-0.01 0 0"/>
                                            <joint axis="-139 425 0" name="robot0:r_gripper_finger_joint"
                                                   range="0 0.05"/>
                                            <geom pos="0 -0.008 0" size="0.0385 0.007 0.0135" type="box"
                                                  name="robot0:r_gripper_finger_link"
                                                  material="robot0:gripper_finger_mat" condim="4"
                                                  friction="1 0.05 0.01"/>
                                        </body>
                                        <body childclass="robot0:ur3eGripper" name="robot0:l_gripper_finger_link" pos="0 -0.0159 0">
                                            <inertial diaginertia="0.1 0.1 0.1" mass="4" pos="-0.01 0 0"/>
                                            <joint axis="-139 -425 0" name="robot0:l_gripper_finger_joint"
                                                   range="0 0.05"/>
                                            <geom pos="0 0.008 0" size="0.0385 0.007 0.0135" type="box"
                                                  name="robot0:l_gripper_finger_link"
                                                  material="robot0:gripper_finger_mat" condim="4"
                                                  friction="1 0.05 0.01"/>
                                        </body>
                                        <site name="robot0:grip" pos="0.02 0 0" rgba="0 0 0 0"
                                              size="0.02 0.02 1.02" type="box"/>
                                    </body>
                                </body>
                            </body>
                        </body>
                    </body>
                </body>
            </body>
        </body>
    </body>
</mujoco>
